<?xml version="1.0"?>
<!-- 
  Mecanum robot URDF with Ridgeback-compatible joint names
  Ridgeback uses: front_left_wheel_joint, front_right_wheel_joint, etc.
-->
<robot name="mecanum_robot">

  <!-- Dummy root avoids KDL warnings about inertia on the root link. -->
  <link name="base_footprint"/>

  <joint name="base_footprint_joint" type="fixed">
    <parent link="base_footprint"/>
    <child link="base_link"/>
    <origin xyz="0 0 0.05" rpy="0 0 0"/>
  </joint>

  <!-- Base Link -->
  <link name="base_link">
    <visual>
      <geometry>
        <box size="0.6 0.4 0.1"/>
      </geometry>
      <material name="blue">
        <color rgba="0.2 0.4 0.8 1.0"/>
      </material>
    </visual>
    <collision>
      <geometry>
        <box size="0.6 0.4 0.1"/>
      </geometry>
    </collision>
    <inertial>
      <mass value="10.0"/>
      <inertia ixx="0.1" ixy="0" ixz="0" iyy="0.1" iyz="0" izz="0.1"/>
    </inertial>
  </link>

  <!-- Front Left Wheel - Ridgeback naming -->
  <link name="front_left_wheel_link">
    <visual>
      <geometry>
        <cylinder radius="0.08" length="0.05"/>
      </geometry>
      <material name="black">
        <color rgba="0.1 0.1 0.1 1.0"/>
      </material>
    </visual>
    <collision>
      <geometry>
        <cylinder radius="0.08" length="0.05"/>
      </geometry>
    </collision>
    <inertial>
      <mass value="1.0"/>
      <inertia ixx="0.01" ixy="0" ixz="0" iyy="0.01" iyz="0" izz="0.01"/>
    </inertial>
  </link>

  <joint name="front_left_wheel_joint" type="continuous">
    <parent link="base_link"/>
    <child link="front_left_wheel_link"/>
    <origin xyz="0.25 0.2 -0.05" rpy="-1.57075 0 0"/>
    <axis xyz="0 0 1"/>
  </joint>

  <!-- Front Right Wheel -->
  <link name="front_right_wheel_link">
    <visual>
      <geometry>
        <cylinder radius="0.08" length="0.05"/>
      </geometry>
      <material name="black"/>
    </visual>
    <collision>
      <geometry>
        <cylinder radius="0.08" length="0.05"/>
      </geometry>
    </collision>
    <inertial>
      <mass value="1.0"/>
      <inertia ixx="0.01" ixy="0" ixz="0" iyy="0.01" iyz="0" izz="0.01"/>
    </inertial>
  </link>

  <joint name="front_right_wheel_joint" type="continuous">
    <parent link="base_link"/>
    <child link="front_right_wheel_link"/>
    <origin xyz="0.25 -0.2 -0.05" rpy="-1.57075 0 0"/>
    <axis xyz="0 0 1"/>
  </joint>

  <!-- Rear Left Wheel -->
  <link name="rear_left_wheel_link">
    <visual>
      <geometry>
        <cylinder radius="0.08" length="0.05"/>
      </geometry>
      <material name="black"/>
    </visual>
    <collision>
      <geometry>
        <cylinder radius="0.08" length="0.05"/>
      </geometry>
    </collision>
    <inertial>
      <mass value="1.0"/>
      <inertia ixx="0.01" ixy="0" ixz="0" iyy="0.01" iyz="0" izz="0.01"/>
    </inertial>
  </link>

  <joint name="rear_left_wheel_joint" type="continuous">
    <parent link="base_link"/>
    <child link="rear_left_wheel_link"/>
    <origin xyz="-0.25 0.2 -0.05" rpy="-1.57075 0 0"/>
    <axis xyz="0 0 1"/>
  </joint>

  <!-- Rear Right Wheel -->
  <link name="rear_right_wheel_link">
    <visual>
      <geometry>
        <cylinder radius="0.08" length="0.05"/>
      </geometry>
      <material name="black"/>
    </visual>
    <collision>
      <geometry>
        <cylinder radius="0.08" length="0.05"/>
      </geometry>
    </collision>
    <inertial>
      <mass value="1.0"/>
      <inertia ixx="0.01" ixy="0" ixz="0" iyy="0.01" iyz="0" izz="0.01"/>
    </inertial>
  </link>

  <joint name="rear_right_wheel_joint" type="continuous">
    <parent link="base_link"/>
    <child link="rear_right_wheel_link"/>
    <origin xyz="-0.25 -0.2 -0.05" rpy="-1.57075 0 0"/>
    <axis xyz="0 0 1"/>
  </joint>

  <transmission name="front_left_wheel_transmission">
    <type>transmission_interface/SimpleTransmission</type>
    <joint name="front_left_wheel_joint">
      <hardwareInterface>hardware_interface/VelocityJointInterface</hardwareInterface>
    </joint>
    <actuator name="front_left_wheel_motor">
      <hardwareInterface>hardware_interface/VelocityJointInterface</hardwareInterface>
      <mechanicalReduction>1</mechanicalReduction>
    </actuator>
  </transmission>

  <transmission name="front_right_wheel_transmission">
    <type>transmission_interface/SimpleTransmission</type>
    <joint name="front_right_wheel_joint">
      <hardwareInterface>hardware_interface/VelocityJointInterface</hardwareInterface>
    </joint>
    <actuator name="front_right_wheel_motor">
      <hardwareInterface>hardware_interface/VelocityJointInterface</hardwareInterface>
      <mechanicalReduction>1</mechanicalReduction>
    </actuator>
  </transmission>

  <transmission name="rear_left_wheel_transmission">
    <type>transmission_interface/SimpleTransmission</type>
    <joint name="rear_left_wheel_joint">
      <hardwareInterface>hardware_interface/VelocityJointInterface</hardwareInterface>
    </joint>
    <actuator name="rear_left_wheel_motor">
      <hardwareInterface>hardware_interface/VelocityJointInterface</hardwareInterface>
      <mechanicalReduction>1</mechanicalReduction>
    </actuator>
  </transmission>

  <transmission name="rear_right_wheel_transmission">
    <type>transmission_interface/SimpleTransmission</type>
    <joint name="rear_right_wheel_joint">
      <hardwareInterface>hardware_interface/VelocityJointInterface</hardwareInterface>
    </joint>
    <actuator name="rear_right_wheel_motor">
      <hardwareInterface>hardware_interface/VelocityJointInterface</hardwareInterface>
      <mechanicalReduction>1</mechanicalReduction>
    </actuator>
  </transmission>

  <!--
    Use Gazebo's official planar move plugin so /cmd_vel can directly move the
    robot in x/y. This keeps the OpenCV -> ROS -> Gazebo communication simple
    and reliable for this project.
  -->
  <gazebo>
    <plugin name="gazebo_ros_planar_move" filename="libgazebo_ros_planar_move.so">
      <commandTopic>cmd_vel</commandTopic>
      <odometryTopic>odom</odometryTopic>
      <odometryFrame>odom</odometryFrame>
      <robotBaseFrame>base_link</robotBaseFrame>
      <odometryRate>50.0</odometryRate>
      <cmdTimeout>0.5</cmdTimeout>
    </plugin>
  </gazebo>

  <!-- Material colors for Gazebo -->
  <gazebo reference="base_link">
    <material>Gazebo/Blue</material>
  </gazebo>

  <gazebo reference="front_left_wheel_link">
    <material>Gazebo/Black</material>
  </gazebo>

  <gazebo reference="front_right_wheel_link">
    <material>Gazebo/Black</material>
  </gazebo>

  <gazebo reference="rear_left_wheel_link">
    <material>Gazebo/Black</material>
  </gazebo>

  <gazebo reference="rear_right_wheel_link">
    <material>Gazebo/Black</material>
  </gazebo>

</robot>
